Workbook
Name \0: #REF!
Name \1: #REF!
Name \a: #REF!
Name \m: #REF!
Name ___sm2: #REF!
Name __SM1: #REF!
Name __SM10: #REF!
Name __SM11: #REF!
Name __SM12: #REF!
Name __sm13: #REF!
Name __SM2: #REF!
Name __SM3: #REF!
Name __SM4: #REF!
Name __SM5: #REF!
Name __SM6: #REF!
Name __SM7: #REF!
Name __SM8: #REF!
Name __SM9: #REF!
Name _l: #REF!
Name _SM1: #REF!
Name _SM10: #REF!
Name _SM11: #REF!
Name _SM12: #REF!
Name _sm13: #REF!
Name _SM2: #REF!
Name _SM3: #REF!
Name _SM4: #REF!
Name _SM5: #REF!
Name _SM6: #REF!
Name _SM7: #REF!
Name _SM8: #REF!
Name _SM9: #REF!
Name _sss: #REF!
Name a: #REF!
Name aaaa: #REF!
Name aaaaaaaaaaa: #REF!
Name AB: #REF!
Name ABREV_E: #REF!
Name Administração: #REF!
Name ALUMÍNIO_2: #REF!
Name ASASASAS: #REF!
Name b: #REF!
Name BDI: 1.43344312465585
Name Betune: #REF!
Name BOLETIM174: #REF!
Name COD_ELE: #REF!
Name comp2: #REF!
Name compinst.: #REF!
Name CRITÉRIOS_IM: #REF!
Name crogr: #REF!
Name d: #REF!
Name dasdfhik: #REF!
Name ddddddd: #REF!
Name DESTINO: #REF!
Name Excel_BuiltIn_Database: #REF!
Name Excel_BuiltIn_Print_Area_1: #REF!
Name f: #REF!
Name fl: #REF!
Name FL_1: #REF!
Name FL_2: #REF!

Sheet Detalhamento - G200
I1: ACOMPANHAMENTO FINANCEIRO
K2: Data de Emissão: 12/05/26
K3: Versão: 00
A4: DETALHAMENTO
A5: CÓDIGO | B5: DESCRIÇÃO | C5: VALOR ORÇADO | D5: ABR | F5: VALOR COMPROMETIDO | G5: SALDO DO COMPROMETIDO | H5: VALOR REALIZADO | I5: PROJEÇÕES | J5: TENDÊNCIA | K5: VARIAÇÃO
A6: 0 | B6: TOTAL OBRA | C6: =SUBTOTAL(9,C7:C253) -> 4.532026e+08 | F6: =SUBTOTAL(9,F7:F253) -> 3.3465024e+08 | G6: =SUBTOTAL(9,G7:G253) -> 1.1855237e+08 | H6: =SUBTOTAL(9,H7:H253) -> 1.0674933e+08 | I6: =SUBTOTAL(9,I7:I253) -> -267155.08 | J6: =SUBTOTAL(9,J7:J253) -> 3.3438308e+08 | K6: =SUBTOTAL(9,K7:K253) -> 1.1881952e+08
A7: 1 | B7: DESPESAS DIRETAS | C7: =SUBTOTAL(9,C8:C109) -> 3.8640159e+08 | D7: =_xlfn.XLOOKUP(A7,'[1]CADASTRO CENTRO DE CUSTO-ALOCAÇ'!$A:$A,'[1]CADASTRO CENTRO DE CUSTO-ALOCAÇ'!$C:$C) -> #N/A | E7: =C7-D7 -> #N/A | F7: =SUBTOTAL(9,F8:F109) -> 2.7037121e+08 | G7: =SUBTOTAL(9,G8:G109) -> 1.1603038e+08 | H7: =SUBTOTAL(9,H8:H109) -> 86608972 | I7: =SUBTOTAL(9,I8:I109) -> -427518.59 | J7: =SUBTOTAL(9,J8:J109) -> 2.6994369e+08 | K7: =SUBTOTAL(9,K8:K109) -> 1.164579e+08
A8: 1001 | B8: GALPÃO G200 | C8: =SUBTOTAL(9,C9:C56) -> 2.0206133e+08 | D8: =_xlfn.XLOOKUP(A8,'[1]CADASTRO CENTRO DE CUSTO-ALOCAÇ'!$A:$A,'[1]CADASTRO CENTRO DE CUSTO-ALOCAÇ'!$C:$C) -> #N/A | E8: =C8-D8 -> #N/A | F8: =SUBTOTAL(9,F9:F56) -> 1.400033e+08 | G8: =SUBTOTAL(9,G9:G56) -> 62058025 | H8: =SUBTOTAL(9,H9:H56) -> 71147139 | I8: =SUBTOTAL(9,I9:I56) -> -1750968.1 | J8: =SUBTOTAL(9,J9:J56) -> 1.3825234e+08 | K8: =SUBTOTAL(9,K9:K56) -> 63808993
A9: 1001001 | B9: PROJETOS E CONSULTORIAS | C9: =SUBTOTAL(9,C10:C11) -> 4318265.1 | D9: =_xlfn.XLOOKUP(A9,'[1]CADASTRO CENTRO DE CUSTO-ALOCAÇ'!$A:$A,'[1]CADASTRO CENTRO DE CUSTO-ALOCAÇ'!$C:$C) -> 4318265.1 | E9: =C9-D9 -> 0 | F9: =SUBTOTAL(9,F10:F11) -> 4160984.3 | G9: =SUBTOTAL(9,G10:G11) -> 157280.79 | H9: =SUBTOTAL(9,H10:H11) -> 826261.2 | I9: =SUBTOTAL(9,I10:I11) -> 0 | J9: =SUBTOTAL(9,J10:J11) -> 4160984.3 | K9: =SUBTOTAL(9,K10:K11) -> 157280.79
A10: 1001001001 | B10: PROJETOS | C10: 2017612.7 | D10: =_xlfn.XLOOKUP(A10,'[1]CADASTRO CENTRO DE CUSTO-ALOCAÇ'!$A:$A,'[1]CADASTRO CENTRO DE CUSTO-ALOCAÇ'!$C:$C) -> 2017612.7 | E10: =C10-D10 -> 0 | F10: =SUMIF('Contratos - G200'!E:E,'Detalhamento - G200'!A10,'Contratos - G200'!J:J)+SUMIF('Pedidos - G200'!D:D,'Detalhamento - G200'!A10,'Pedidos - G200'!H:H) -> 2005691.7 | G10: =C10-F10 -> 11921 | H10: =SUMIF('Notas fiscais - G200'!D:D,'Detalhamento - G200'!A10,'Notas fiscais - G200'!T:T) -> 654946.18 | I10: =VLOOKUP(A10,'Projeções - G200'!B:F,5,FALSE) -> 0 | J10: =F10+I10 -> 2005691.7 | K10: =C10-J10 -> 11921
A11: 1001001002 | B11: ENSAIOS E CONSULTORIAS | C11: 2300652.4 | D11: =_xlfn.XLOOKUP(A11,'[1]CADASTRO CENTRO DE CUSTO-ALOCAÇ'!$A:$A,'[1]CADASTRO CENTRO DE CUSTO-ALOCAÇ'!$C:$C) -> 2300652.4 | E11: =C11-D11 -> 0 | F11: =SUMIF('Contratos - G200'!E:E,'Detalhamento - G200'!A11,'Contratos - G200'!J:J)+SUMIF('Pedidos - G200'!D:D,'Detalhamento - G200'!A11,'Pedidos - G200'!H:H) -> 2155292.6 | G11: =C11-F11 -> 145359.79 | H11: =SUMIF('Notas fiscais - G200'!D:D,'Detalhamento - G200'!A11,'Notas fiscais - G200'!T:T) -> 171315.02 | I11: =VLOOKUP(A11,'Projeções - G200'!B:F,5,FALSE) -> 0 | J11: =F11+I11 -> 2155292.6 | K11: =C11-J11 -> 145359.79
A12: 1001002 | B12: TERRAPLENAGEM, CONTENÇÃO E DRENAGEM | C12: =SUBTOTAL(9,C13:C19) -> 39946136 | D12: =_xlfn.XLOOKUP(A12,'[1]CADASTRO CENTRO DE CUSTO-ALOCAÇ'!$A:$A,'[1]CADASTRO CENTRO DE CUSTO-ALOCAÇ'!$C:$C) -> #N/A | E12: =C12-D12 -> #N/A | F12: =SUBTOTAL(9,F13:F19) -> 34428613 | G12: =SUBTOTAL(9,G13:G19) -> 5517522.9 | H12: =SUBTOTAL(9,H13:H19) -> 13951581 | I12: =SUBTOTAL(9,I13:I19) -> 0 | J12: =SUBTOTAL(9,J13:J19) -> 34428613 | K12: =SUBTOTAL(9,K13:K19) -> 5517522.9
A13: 1001002002 | B13: MOVIMENTO DE TERRA - ESCOPO MÍNIMO | C13: 4636906.6 | D13: =_xlfn.XLOOKUP(A13,'[1]CADASTRO CENTRO DE CUSTO-ALOCAÇ'!$A:$A,'[1]CADASTRO CENTRO DE CUSTO-ALOCAÇ'!$C:$C) -> 4636906.6 | E13: =C13-D13 -> 0 | F13: =SUMIF('Contratos - G200'!E:E,'Detalhamento - G200'!A13,'Contratos - G200'!J:J)+SUMIF('Pedidos - G200'!D:D,'Detalhamento - G200'!A13,'Pedidos - G200'!H:H) -> 4636906.6 | G13: =C13-F13 -> 0 | H13: =SUMIF('Notas fiscais - G200'!D:D,'Detalhamento - G200'!A13,'Notas fiscais - G200'!T:T) -> 4434001.7 | I13: =VLOOKUP(A13,'Projeções - G200'!B:F,5,FALSE) -> 0 | J13: =F13+I13 -> 4636906.6 | K13: =C13-J13 -> 0
A14: 1001002003 | B14: MOVIMENTAÇÃO DE TERRA | C14: 22691172 | D14: =_xlfn.XLOOKUP(A14,'[1]CADASTRO CENTRO DE CUSTO-ALOCAÇ'!$A:$A,'[1]CADASTRO CENTRO DE CUSTO-ALOCAÇ'!$C:$C) -> 22691172 | E14: =C14-D14 -> 0 | F14: =SUMIF('Contratos - G200'!E:E,'Detalhamento - G200'!A14,'Contratos - G200'!J:J)+SUMIF('Pedidos - G200'!D:D,'Detalhamento - G200'!A14,'Pedidos - G200'!H:H) -> 22341905 | G14: =C14-F14 -> 349267 | H14: =SUMIF('Notas fiscais - G200'!D:D,'Detalhamento - G200'!A14,'Notas fiscais - G200'!T:T) -> 7771538.4 | I14: =VLOOKUP(A14,'Projeções - G200'!B:F,5,FALSE) -> 0 | J14: =F14+I14 -> 22341905 | K14: =C14-J14 -> 349267
A15: 1001002004 | B15: LINHA DE VIDA MOVEL PARA TALUDES | C15: 80552.54 | D15: =_xlfn.XLOOKUP(A15,'[1]CADASTRO CENTRO DE CUSTO-ALOCAÇ'!$A:$A,'[1]CADASTRO CENTRO DE CUSTO-ALOCAÇ'!$C:$C) -> 80552.54 | E15: =C15-D15 -> 0 | F15: =SUMIF('Contratos - G200'!E:E,'Detalhamento - G200'!A15,'Contratos - G200'!J:J)+SUMIF('Pedidos - G200'!D:D,'Detalhamento - G200'!A15,'Pedidos - G200'!H:H) -> 0 | G15: =C15-F15 -> 80552.54 | H15: =SUMIF('Notas fiscais - G200'!D:D,'Detalhamento - G200'!A15,'Notas fiscais - G200'!T:T) -> 0 | I15: =VLOOKUP(A15,'Projeções - G200'!B:F,5,FALSE) -> 0 | J15: =F15+I15 -> 0 | K15: =C15-J15 -> 80552.54
A16: 1001002005 | B16: HIDROSSEMEADURA | C16: 712470 | D16: =_xlfn.XLOOKUP(A16,'[1]CADASTRO CENTRO DE CUSTO-ALOCAÇ'!$A:$A,'[1]CADASTRO CENTRO DE CUSTO-ALOCAÇ'!$C:$C) -> 712470 | E16: =C16-D16 -> 0 | F16: =SUMIF('Contratos - G200'!E:E,'Detalhamento - G200'!A16,'Contratos - G200'!J:J)+SUMIF('Pedidos - G200'!D:D,'Detalhamento - G200'!A16,'Pedidos - G200'!H:H) -> 575368.71 | G16: =C16-F16 -> 137101.29 | H16: =SUMIF('Notas fiscais - G200'!D:D,'Detalhamento - G200'!A16,'Notas fiscais - G200'!T:T) -> 0 | I16: =VLOOKUP(A16,'Projeções - G200'!B:F,5,FALSE) -> 0 | J16: =F16+I16 -> 575368.71 | K16: =C16-J16 -> 137101.29
A17: 1001002006 | B17: CONTENÇÕES | C17: 6392000 | D17: =_xlfn.XLOOKUP(A17,'[1]CADASTRO CENTRO DE CUSTO-ALOCAÇ'!$A:$A,'[1]CADASTRO CENTRO DE CUSTO-ALOCAÇ'!$C:$C) -> 6392000 | E17: =C17-D17 -> 0 | F17: =SUMIF('Contratos - G200'!E:E,'Detalhamento - G200'!A17,'Contratos - G200'!J:J)+SUMIF('Pedidos - G200'!D:D,'Detalhamento - G200'!A17,'Pedidos - G200'!H:H) -> 5727065.1 | G17: =C17-F17 -> 664934.9 | H17: =SUMIF('Notas fiscais - G200'!D:D,'Detalhamento - G200'!A17,'Notas fiscais - G200'!T:T) -> 1598299.8 | I17: =VLOOKUP(A17,'Projeções - G200'!B:F,5,FALSE) -> 0 | J17: =F17+I17 -> 5727065.1 | K17: =C17-J17 -> 664934.9
A18: 1001002007 | B18: ESCAVAÇÃO NO TARDOZ | C18: 800400 | D18: =_xlfn.XLOOKUP(A18,'[1]CADASTRO CENTRO DE CUSTO-ALOCAÇ'!$A:$A,'[1]CADASTRO CENTRO DE CUSTO-ALOCAÇ'!$C:$C) -> 800400 | E18: =C18-D18 -> 0 | F18: =SUMIF('Contratos - G200'!E:E,'Detalhamento - G200'!A18,'Contratos - G200'!J:J)+SUMIF('Pedidos - G200'!D:D,'Detalhamento - G200'!A18,'Pedidos - G200'!H:H) -> 800400.01 | G18: =C18-F18 -> -0.01 | H18: =SUMIF('Notas fiscais - G200'!D:D,'Detalhamento - G200'!A18,'Notas fiscais - G200'!T:T) -> 136068.71 | I18: =VLOOKUP(A18,'Projeções - G200'!B:F,5,FALSE) -> 0 | J18: =F18+I18 -> 800400.01 | K18: =C18-J18 -> -0.01
A19: 1001002008 | B19: DRENAGEM | C19: 4632635.2 | D19: =_xlfn.XLOOKUP(A19,'[1]CADASTRO CENTRO DE CUSTO-ALOCAÇ'!$A:$A,'[1]CADASTRO CENTRO DE CUSTO-ALOCAÇ'!$C:$C) -> 4632635.2 | E19: =C19-D19 -> 0 | F19: =SUMIF('Contratos - G200'!E:E,'Detalhamento - G200'!A19,'Contratos - G200'!J:J)+SUMIF('Pedidos - G200'!D:D,'Detalhamento - G200'!A19,'Pedidos - G200'!H:H) -> 346968.04 | G19: =C19-F19 -> 4285667.1 | H19: =SUMIF('Notas fiscais - G200'!D:D,'Detalhamento - G200'!A19,'Notas fiscais - G200'!T:T) -> 11672.07 | I19: =VLOOKUP(A19,'Projeções - G200'!B:F,5,FALSE) -> 0 | J19: =F19+I19 -> 346968.04 | K19: =C19-J19 -> 4285667.1
A20: 1001003 | B20: GALPÃO PRINCIPAL | C20: =SUBTOTAL(9,C21:C34) -> 86690399 | D20: =_xlfn.XLOOKUP(A20,'[1]CADASTRO CENTRO DE CUSTO-ALOCAÇ'!$A:$A,'[1]CADASTRO CENTRO DE CUSTO-ALOCAÇ'!$C:$C) -> #N/A | E20: =C20-D20 -> #N/A | F20: =SUBTOTAL(9,F21:F34) -> 65637369 | G20: =SUBTOTAL(9,G21:G34) -> 21053030 | H20: =SUBTOTAL(9,H21:H34) -> 42534556 | I20: =SUBTOTAL(9,I21:I34) -> -646893.62 | J20: =SUBTOTAL(9,J21:J34) -> 64990475 | K20: =SUBTOTAL(9,K21:K34) -> 21699924
A21: 1001003001 | B21: FUNDAÇÃO GALPÃO | C21: 9773681.3 | D21: =_xlfn.XLOOKUP(A21,'[1]CADASTRO CENTRO DE CUSTO-ALOCAÇ'!$A:$A,'[1]CADASTRO CENTRO DE CUSTO-ALOCAÇ'!$C:$C) -> 9773681.3 | E21: =C21-D21 -> 0 | F21: =SUMIF('Contratos - G200'!E:E,'Detalhamento - G200'!A21,'Contratos - G200'!J:J)+SUMIF('Pedidos - G200'!D:D,'Detalhamento - G200'!A21,'Pedidos - G200'!H:H) -> 7710689.8 | G21: =C21-F21 -> 2062991.5 | H21: =SUMIF('Notas fiscais - G200'!D:D,'Detalhamento - G200'!A21,'Notas fiscais - G200'!T:T) -> 893277.54 | I21: =VLOOKUP(A21,'Projeções - G200'!B:F,5,FALSE) -> 0 | J21: =F21+I21 -> 7710689.8 | K21: =C21-J21 -> 2062991.5
A22: 1001003002 | B22: SUPERESTRUTURA GALPÃO | C22: 12610439 | D22: =_xlfn.XLOOKUP(A22,'[1]CADASTRO CENTRO DE CUSTO-ALOCAÇ'!$A:$A,'[1]CADASTRO CENTRO DE CUSTO-ALOCAÇ'!$C:$C) -> 12610439 | E22: =C22-D22 -> 0 | F22: =SUMIF('Contratos - G200'!E:E,'Detalhamento - G200'!A22,'Contratos - G200'!J:J)+SUMIF('Pedidos - G200'!D:D,'Detalhamento - G200'!A22,'Pedidos - G200'!H:H) -> 14432797 | G22: =C22-F22 -> -1822357.6 | H22: =SUMIF('Notas fiscais - G200'!D:D,'Detalhamento - G200'!A22,'Notas fiscais - G200'!T:T) -> 38764242 | I22: =VLOOKUP(A22,'Projeções - G200'!B:F,5,FALSE) -> 0 | J22: =F22+I22 -> 14432797 | K22: =C22-J22 -> -1822357.6
A23: 1001003003 | B23: COBERTURA E FECHAMENTO METALICO | C23: 39714155 | D23: =_xlfn.XLOOKUP(A23,'[1]CADASTRO CENTRO DE CUSTO-ALOCAÇ'!$A:$A,'[1]CADASTRO CENTRO DE CUSTO-ALOCAÇ'!$C:$C) -> 39714155 | E23: =C23-D23 -> 0 | F23: =SUMIF('Contratos - G200'!E:E,'Detalhamento - G200'!A23,'Contratos - G200'!J:J)+SUMIF('Pedidos - G200'!D:D,'Detalhamento - G200'!A23,'Pedidos - G200'!H:H) -> 39251594 | G23: =C23-F23 -> 462561 | H23: =SUMIF('Notas fiscais - G200'!D:D,'Detalhamento - G200'!A23,'Notas fiscais - G200'!T:T) -> 0 | I23: =VLOOKUP(A23,'Projeções - G200'!B:F,5,FALSE) -> 0 | J23: =F23+I23 -> 39251594 | K23: =C23-J23 -> 462561
A24: 1001003004 | B24: PISO DE CONCRETO | C24: 16686202 | D24: =_xlfn.XLOOKUP(A24,'[1]CADASTRO CENTRO DE CUSTO-ALOCAÇ'!$A:$A,'[1]CADASTRO CENTRO DE CUSTO-ALOCAÇ'!$C:$C) -> 16686202 | E24: =C24-D24 -> 0 | F24: =SUMIF('Contratos - G200'!E:E,'Detalhamento - G200'!A24,'Contratos - G200'!J:J)+SUMIF('Pedidos - G200'!D:D,'Detalhamento - G200'!A24,'Pedidos - G200'!H:H) -> 0 | G24: =C24-F24 -> 16686202 | H24: =SUMIF('Notas fiscais - G200'!D:D,'Detalhamento - G200'!A24,'Notas fiscais - G200'!T:T) -> 0 | I24: =VLOOKUP(A24,'Projeções - G200'!B:F,5,FALSE) -> 0 | J24: =F24+I24 -> 0 | K24: =C24-J24 -> 16686202
A25: 1001003005 | B25: ESQUADRIAS E CAIXILHOS | C25: 2316824.1 | D25: =_xlfn.XLOOKUP(A25,'[1]CADASTRO CENTRO DE CUSTO-ALOCAÇ'!$A:$A,'[1]CADASTRO CENTRO DE CUSTO-ALOCAÇ'!$C:$C) -> 2316824.1 | E25: =C25-D25 -> 0 | F25: =SUMIF('Contratos - G200'!E:E,'Detalhamento - G200'!A25,'Contratos - G200'!J:J)+SUMIF('Pedidos - G200'!D:D,'Detalhamento - G200'!A25,'Pedidos - G200'!H:H) -> 1450590 | G25: =C25-F25 -> 866234.14 | H25: =SUMIF('Notas fiscais - G200'!D:D,'Detalhamento - G200'!A25,'Notas fiscais - G200'!T:T) -> 1112193 | I25: =VLOOKUP(A25,'Projeções - G200'!B:F,5,FALSE) -> 0 | J25: =F25+I25 -> 1450590 | K25: =C25-J25 -> 866234.14
A26: 1001003006 | B26: IMPERMEABILIZAÇÃO | C26: 750757.69 | D26: =_xlfn.XLOOKUP(A26,'[1]CADASTRO CENTRO DE CUSTO-ALOCAÇ'!$A:$A,'[1]CADASTRO CENTRO DE CUSTO-ALOCAÇ'!$C:$C) -> 750757.69 | E26: =C26-D26 -> 0 | F26: =SUMIF('Contratos - G200'!E:E,'Detalhamento - G200'!A26,'Contratos - G200'!J:J)+SUMIF('Pedidos - G200'!D:D,'Detalhamento - G200'!A26,'Pedidos - G200'!H:H) -> 30241.363 | G26: =C26-F26 -> 720516.33 | H26: =SUMIF('Notas fiscais - G200'!D:D,'Detalhamento - G200'!A26,'Notas fiscais - G200'!T:T) -> 1017.32 | I26: =VLOOKUP(A26,'Projeções - G200'!B:F,5,FALSE) -> 0 | J26: =F26+I26 -> 30241.363 | K26: =C26-J26 -> 720516.33
A27: 1001003007 | B27: REVESTIMENTOS | C27: 0 | D27: =_xlfn.XLOOKUP(A27,'[1]CADASTRO CENTRO DE CUSTO-ALOCAÇ'!$A:$A,'[1]CADASTRO CENTRO DE CUSTO-ALOCAÇ'!$C:$C) -> 0 | E27: =C27-D27 -> 0 | F27: =SUMIF('Contratos - G200'!E:E,'Detalhamento - G200'!A27,'Contratos - G200'!J:J)+SUMIF('Pedidos - G200'!D:D,'Detalhamento - G200'!A27,'Pedidos - G200'!H:H) -> 0 | G27: =C27-F27 -> 0 | H27: =SUMIF('Notas fiscais - G200'!D:D,'Detalhamento - G200'!A27,'Notas fiscais - G200'!T:T) -> 0 | I27: =VLOOKUP(A27,'Projeções - G200'!B:F,5,FALSE) -> 0 | J27: =F27+I27 -> 0 | K27: =C27-J27 -> 0
A28: 1001003008 | B28: FORRO | C28: 0 | D28: =_xlfn.XLOOKUP(A28,'[1]CADASTRO CENTRO DE CUSTO-ALOCAÇ'!$A:$A,'[1]CADASTRO CENTRO DE CUSTO-ALOCAÇ'!$C:$C) -> 0 | E28: =C28-D28 -> 0 | F28: =SUMIF('Contratos - G200'!E:E,'Detalhamento - G200'!A28,'Contratos - G200'!J:J)+SUMIF('Pedidos - G200'!D:D,'Detalhamento - G200'!A28,'Pedidos - G200'!H:H) -> 0 | G28: =C28-F28 -> 0 | H28: =SUMIF('Notas fiscais - G200'!D:D,'Detalhamento - G200'!A28,'Notas fiscais - G200'!T:T) -> 0 | I28: =VLOOKUP(A28,'Projeções - G200'!B:F,5,FALSE) -> 0 | J28: =F28+I28 -> 0 | K28: =C28-J28 -> 0
A29: 1001003009 | B29: LOUÇAS, METAIS E INSTALAÇÕES DE BANHEIRO | C29: 0 | D29: =_xlfn.XLOOKUP(A29,'[1]CADASTRO CENTRO DE CUSTO-ALOCAÇ'!$A:$A,'[1]CADASTRO CENTRO DE CUSTO-ALOCAÇ'!$C:$C) -> 0 | E29: =C29-D29 -> 0 | F29: =SUMIF('Contratos - G200'!E:E,'Detalhamento - G200'!A29,'Contratos - G200'!J:J)+SUMIF('Pedidos - G200'!D:D,'Detalhamento - G200'!A29,'Pedidos - G200'!H:H) -> 0 | G29: =C29-F29 -> 0 | H29: =SUMIF('Notas fiscais - G200'!D:D,'Detalhamento - G200'!A29,'Notas fiscais - G200'!T:T) -> 0 | I29: =VLOOKUP(A29,'Projeções - G200'!B:F,5,FALSE) -> 0 | J29: =F29+I29 -> 0 | K29: =C29-J29 -> 0
A30: 1001003010 | B30: SERRALHERIA GALPÃO | C30: 779756.42 | D30: =_xlfn.XLOOKUP(A30,'[1]CADASTRO CENTRO DE CUSTO-ALOCAÇ'!$A:$A,'[1]CADASTRO CENTRO DE CUSTO-ALOCAÇ'!$C:$C) -> 779756.42 | E30: =C30-D30 -> 0 | F30: =SUMIF('Contratos - G200'!E:E,'Detalhamento - G200'!A30,'Contratos - G200'!J:J)+SUMIF('Pedidos - G200'!D:D,'Detalhamento - G200'!A30,'Pedidos - G200'!H:H) -> 611161.88 | G30: =C30-F30 -> 168594.54 | H30: =SUMIF('Notas fiscais - G200'!D:D,'Detalhamento - G200'!A30,'Notas fiscais - G200'!T:T) -> 115550.02 | I30: =VLOOKUP(A30,'Projeções - G200'!B:F,5,FALSE) -> 0 | J30: =F30+I30 -> 611161.88 | K30: =C30-J30 -> 168594.54
A31: 1001003011 | B31: EQUIPAMENTOS GALPÃO | C31: 2965707.5 | D31: =_xlfn.XLOOKUP(A31,'[1]CADASTRO CENTRO DE CUSTO-ALOCAÇ'!$A:$A,'[1]CADASTRO CENTRO DE CUSTO-ALOCAÇ'!$C:$C) -> 2965707.5 | E31: =C31-D31 -> 0 | F31: =SUMIF('Contratos - G200'!E:E,'Detalhamento - G200'!A31,'Contratos - G200'!J:J)+SUMIF('Pedidos - G200'!D:D,'Detalhamento - G200'!A31,'Pedidos - G200'!H:H) -> 2149410 | G31: =C31-F31 -> 816297.48 | H31: =SUMIF('Notas fiscais - G200'!D:D,'Detalhamento - G200'!A31,'Notas fiscais - G200'!T:T) -> 1648276.1 | I31: =VLOOKUP(A31,'Projeções - G200'!B:F,5,FALSE) -> -646893.62 | J31: =F31+I31 -> 1502516.4 | K31: =C31-J31 -> 1463191.1
A32: 1001003012 | B32: PINTURA GALPÃO | C32: 311057.28 | D32: =_xlfn.XLOOKUP(A32,'[1]CADASTRO CENTRO DE CUSTO-ALOCAÇ'!$A:$A,'[1]CADASTRO CENTRO DE CUSTO-ALOCAÇ'!$C:$C) -> 311057.28 | E32: =C32-D32 -> 0 | F32: =SUMIF('Contratos - G200'!E:E,'Detalhamento - G200'!A32,'Contratos - G200'!J:J)+SUMIF('Pedidos - G200'!D:D,'Detalhamento - G200'!A32,'Pedidos - G200'!H:H) -> 0 | G32: =C32-F32 -> 311057.28 | H32: =SUMIF('Notas fiscais - G200'!D:D,'Detalhamento - G200'!A32,'Notas fiscais - G200'!T:T) -> 0 | I32: =VLOOKUP(A32,'Projeções - G200'!B:F,5,FALSE) -> 0 | J32: =F32+I32 -> 0 | K32: =C32-J32 -> 311057.28
... A34: 1001003014 | B34: COMUNICAÇÃO VISUAL GALPÃO | C34: 0 | D34: =_xlfn.XLOOKUP(A34,'[1]CADASTRO CENTRO DE CUSTO-ALOCAÇ'!$A:$A,'[1]CADASTRO CENTRO DE CUSTO-ALOCAÇ'!$C:$C) -> 0 | E34: =C34-D34 -> 0 | F34: =SUMIF('Contratos - G200'!E:E,'Detalhamento - G200'!A34,'Contratos - G200'!J:J)+SUMIF('Pedidos - G200'!D:D,'Detalhamento - G200'!A34,'Pedidos - G200'!H:H) -> 885 | G34: =C34-F34 -> -885 | H34: =SUMIF('Notas fiscais - G200'!D:D,'Detalhamento - G200'!A34,'Notas fiscais - G200'!T:T) -> 0 | I34: =VLOOKUP(A34,'Projeções - G200'!B:F,5,FALSE) -> 0 | J34: =F34+I34 -> 885 | K34: =C34-J34 -> -885
A35: 1001004 | B35: OUTRAS EDIFICAÇÕES | C35: =SUBTOTAL(9,C36:C45) -> 23248542 | D35: =_xlfn.XLOOKUP(A35,'[1]CADASTRO CENTRO DE CUSTO-ALOCAÇ'!$A:$A,'[1]CADASTRO CENTRO DE CUSTO-ALOCAÇ'!$C:$C) -> 23248542 | E35: =C35-D35 -> 0 | F35: =SUBTOTAL(9,F36:F45) -> 9355187.5 | G35: =SUBTOTAL(9,G36:G45) -> 13893355 | H35: =SUBTOTAL(9,H36:H45) -> 29165.31 | I35: =SUBTOTAL(9,I36:I45) -> 0 | J35: =SUBTOTAL(9,J36:J45) -> 9355187.5 | K35: =SUBTOTAL(9,K36:K45) -> 13893355
A36: 1001004001 | B36: PORTARIA / COBERTURA DA ECLUSA | C36: 4576075.6 | D36: =_xlfn.XLOOKUP(A36,'[1]CADASTRO CENTRO DE CUSTO-ALOCAÇ'!$A:$A,'[1]CADASTRO CENTRO DE CUSTO-ALOCAÇ'!$C:$C) -> 4576075.6 | E36: =C36-D36 -> 0 | F36: =SUMIF('Contratos - G200'!E:E,'Detalhamento - G200'!A36,'Contratos - G200'!J:J)+SUMIF('Pedidos - G200'!D:D,'Detalhamento - G200'!A36,'Pedidos - G200'!H:H) -> 2882643.7 | G36: =C36-F36 -> 1693431.9 | H36: =SUMIF('Notas fiscais - G200'!D:D,'Detalhamento - G200'!A36,'Notas fiscais - G200'!T:T) -> 0 | I36: =VLOOKUP(A36,'Projeções - G200'!B:F,5,FALSE) -> 0 | J36: =F36+I36 -> 2882643.7 | K36: =C36-J36 -> 1693431.9
A37: 1001004002 | B37: APOIO (VESTIÁRIO + REFEITÓRIO) | C37: 9253125 | D37: =_xlfn.XLOOKUP(A37,'[1]CADASTRO CENTRO DE CUSTO-ALOCAÇ'!$A:$A,'[1]CADASTRO CENTRO DE CUSTO-ALOCAÇ'!$C:$C) -> 9253125 | E37: =C37-D37 -> 0 | F37: =SUMIF('Contratos - G200'!E:E,'Detalhamento - G200'!A37,'Contratos - G200'!J:J)+SUMIF('Pedidos - G200'!D:D,'Detalhamento - G200'!A37,'Pedidos - G200'!H:H) -> 2739057.3 | G37: =C37-F37 -> 6514067.7 | H37: =SUMIF('Notas fiscais - G200'!D:D,'Detalhamento - G200'!A37,'Notas fiscais - G200'!T:T) -> 15983.14 | I37: =VLOOKUP(A37,'Projeções - G200'!B:F,5,FALSE) -> 0 | J37: =F37+I37 -> 2739057.3 | K37: =C37-J37 -> 6514067.7
A38: 1001004003 | B38: COBERTURA PEDESTRES | C38: 0 | D38: =_xlfn.XLOOKUP(A38,'[1]CADASTRO CENTRO DE CUSTO-ALOCAÇ'!$A:$A,'[1]CADASTRO CENTRO DE CUSTO-ALOCAÇ'!$C:$C) -> 0 | E38: =C38-D38 -> 0 | F38: =SUMIF('Contratos - G200'!E:E,'Detalhamento - G200'!A38,'Contratos - G200'!J:J)+SUMIF('Pedidos - G200'!D:D,'Detalhamento - G200'!A38,'Pedidos - G200'!H:H) -> 0 | G38: =C38-F38 -> 0 | H38: =SUMIF('Notas fiscais - G200'!D:D,'Detalhamento - G200'!A38,'Notas fiscais - G200'!T:T) -> 0 | I38: =VLOOKUP(A38,'Projeções - G200'!B:F,5,FALSE) -> 0 | J38: =F38+I38 -> 0 | K38: =C38-J38 -> 0
A39: 1001004004 | B39: APOIO MOTORISTA | C39: 0 | D39: =_xlfn.XLOOKUP(A39,'[1]CADASTRO CENTRO DE CUSTO-ALOCAÇ'!$A:$A,'[1]CADASTRO CENTRO DE CUSTO-ALOCAÇ'!$C:$C) -> 0 | E39: =C39-D39 -> 0 | F39: =SUMIF('Contratos - G200'!E:E,'Detalhamento - G200'!A39,'Contratos - G200'!J:J)+SUMIF('Pedidos - G200'!D:D,'Detalhamento - G200'!A39,'Pedidos - G200'!H:H) -> 0 | G39: =C39-F39 -> 0 | H39: =SUMIF('Notas fiscais - G200'!D:D,'Detalhamento - G200'!A39,'Notas fiscais - G200'!T:T) -> 0 | I39: =VLOOKUP(A39,'Projeções - G200'!B:F,5,FALSE) -> 0 | J39: =F39+I39 -> 0 | K39: =C39-J39 -> 0
A40: 1001004005 | B40: UTILIDADES | C40: 1094800 | D40: =_xlfn.XLOOKUP(A40,'[1]CADASTRO CENTRO DE CUSTO-ALOCAÇ'!$A:$A,'[1]CADASTRO CENTRO DE CUSTO-ALOCAÇ'!$C:$C) -> 1094800 | E40: =C40-D40 -> 0 | F40: =SUMIF('Contratos - G200'!E:E,'Detalhamento - G200'!A40,'Contratos - G200'!J:J)+SUMIF('Pedidos - G200'!D:D,'Detalhamento - G200'!A40,'Pedidos - G200'!H:H) -> 192891.6 | G40: =C40-F40 -> 901908.4 | H40: =SUMIF('Notas fiscais - G200'!D:D,'Detalhamento - G200'!A40,'Notas fiscais - G200'!T:T) -> 1634.24 | I40: =VLOOKUP(A40,'Projeções - G200'!B:F,5,FALSE) -> 0 | J40: =F40+I40 -> 192891.6 | K40: =C40-J40 -> 901908.4
A41: 1001004006 | B41: SANITÁRIOS EXTERNOS AO GALPÃO | C41: 4091136.1 | D41: =_xlfn.XLOOKUP(A41,'[1]CADASTRO CENTRO DE CUSTO-ALOCAÇ'!$A:$A,'[1]CADASTRO CENTRO DE CUSTO-ALOCAÇ'!$C:$C) -> 4091136.1 | E41: =C41-D41 -> 0 | F41: =SUMIF('Contratos - G200'!E:E,'Detalhamento - G200'!A41,'Contratos - G200'!J:J)+SUMIF('Pedidos - G200'!D:D,'Detalhamento - G200'!A41,'Pedidos - G200'!H:H) -> 740085.44 | G41: =C41-F41 -> 3351050.7 | H41: =SUMIF('Notas fiscais - G200'!D:D,'Detalhamento - G200'!A41,'Notas fiscais - G200'!T:T) -> 11547.93 | I41: =VLOOKUP(A41,'Projeções - G200'!B:F,5,FALSE) -> 0 | J41: =F41+I41 -> 740085.44 | K41: =C41-J41 -> 3351050.7
...

Sheet Pedidos - G200
I1: BASE SIENGE | J1: MÊS
B2: Instruções: | C2: No Sienge (Suprimentos / Contratos e Medições / Relatórios / Contratos / Faturamentos diretos);
C3: Obras 152/ Consultar / Gerar relatório excel;
B4: Observação: | C4: Esta planilha serva para a aba "analítico" não duplicar os custos, ou seja, para não associar as notas como uma nova contratação e estourar um saldo já contratado. Não preencher a coluna "F" com absolutamente nenhum caracter se não for vinculado a um contrato
I5: 32280 | J5: Fev
I6: 5422769.2 | J6: março
I7: 14890073 | J7: abril
J8: maio
D11: TOTAL | F11: =SUBTOTAL(9,F14:F1048576) -> 26099070 | G11: =F11-H11 -> 15635731 | H11: =SUBTOTAL(9,H14:H1048576) -> 10463339
A13: MÊS | B13: PEDIDO | C13: CREDOR | D13: APROPRIAÇÃO | E13: DESCRIÇÃO DA EAP | F13: VALOR | G13: VÍNCULO DE FATURAMENTO DIRETO | H13: VALOR À CONSIDERAR
A14: Fev | B14: PPC/25660 | C14: SOLUCAO TOLDOS EIRELI | D14: 2001001007 | E14: =_xlfn.XLOOKUP(D14,'Detalhamento - G200'!A:A,'Detalhamento - G200'!B:B,0) -> LOCAÇÃO DE TOLDO | F14: =32280 -> 32280 | H14: =IF(G14<>"",0,F14) -> 32280
A15: Mar | B15: PPC/26418 | C15: HIDRO LOGICA CONSULTORIA E TREINAMENTO LTDA | D15: 1001001001 | E15: =_xlfn.XLOOKUP(D15,'Detalhamento - G200'!A:A,'Detalhamento - G200'!B:B,0) -> PROJETOS | F15: 7000 | H15: =IF(G15<>"",0,F15) -> 7000
A16: Mar | B16: PPC/26511 | C16: A J S SOUZA SERVICOS GRAFICOS | D16: 2001001006 | E16: =_xlfn.XLOOKUP(D16,'Detalhamento - G200'!A:A,'Detalhamento - G200'!B:B,0) -> IMPLANTAÇÃO DE CANTEIRO - CIVIL | F16: 11921 | H16: =IF(G16<>"",0,F16) -> 11921
A17: Mar | B17: PPC/26526 | C17: HD MORENO - COMÉRCIO E SERVIÇOS METALURGICOS EIRELI | D17: 1001003002 | E17: =_xlfn.XLOOKUP(D17,'Detalhamento - G200'!A:A,'Detalhamento - G200'!B:B,0) -> SUPERESTRUTURA GALPÃO | F17: 3350 | H17: =IF(G17<>"",0,F17) -> 3350
A18: Mar | B18: PPC/26527 | C18: PARATEC - PARA RAIOS E ACESSORIOS LTDA | D18: 1001003002 | E18: =_xlfn.XLOOKUP(D18,'Detalhamento - G200'!A:A,'Detalhamento - G200'!B:B,0) -> SUPERESTRUTURA GALPÃO | F18: 23458 | H18: =IF(G18<>"",0,F18) -> 23458
A19: Mar | B19: PPC/26557 | C19: GENERAL WIRING DO BRASIL INDUSTRIA E COMERCIO EIRELI | D19: 1001002006 | E19: =_xlfn.XLOOKUP(D19,'Detalhamento - G200'!A:A,'Detalhamento - G200'!B:B,0) -> CONTENÇÕES | F19: 3111.6 | G19: CLSF/200-3-039 | H19: =IF(G19<>"",0,F19) -> 0
A20: Mar | B20: PPC/26562 | C20: FORTLEV INDUSTRIA E COMERCIO DE PLASTICOS LTDA | D20: 1001002006 | E20: =_xlfn.XLOOKUP(D20,'Detalhamento - G200'!A:A,'Detalhamento - G200'!B:B,0) -> CONTENÇÕES | F20: 10620.67 | G20: CLSF/200-3-039 | H20: =IF(G20<>"",0,F20) -> 0
A21: Mar | B21: PPC/26564 | C21: ANTONIO CARDOSO MARTINS | D21: 1001002006 | E21: =_xlfn.XLOOKUP(D21,'Detalhamento - G200'!A:A,'Detalhamento - G200'!B:B,0) -> CONTENÇÕES | F21: 34650 | G21: CLSF/200-3-039 | H21: =IF(G21<>"",0,F21) -> 0
A22: Mar | B22: PPC/26565 | C22: ADUANA COMERCIO DE GEOSSINTETICOS LTDA | D22: 1001002006 | E22: =_xlfn.XLOOKUP(D22,'Detalhamento - G200'!A:A,'Detalhamento - G200'!B:B,0) -> CONTENÇÕES | F22: 4972 | G22: CLSF/200-3-039 | H22: =IF(G22<>"",0,F22) -> 0
A23: Mar | B23: PPC/26595 | C23: GERACAO E ENERGIA SERVICOS E COMERCIO LTDA | D23: 2001001003 | E23: =_xlfn.XLOOKUP(D23,'Detalhamento - G200'!A:A,'Detalhamento - G200'!B:B,0) -> GERADOR BACK-UP | F23: 9000 | H23: =IF(G23<>"",0,F23) -> 9000
A24: Mar | B24: PPC/26618 | C24: BAHIATECH MATERIAIS ELETRICOS LTDA | D24: 2001001002 | E24: =_xlfn.XLOOKUP(D24,'Detalhamento - G200'!A:A,'Detalhamento - G200'!B:B,0) -> IMPLANTAÇÃO DE CANTEIRO - ELETRICA | F24: 6620.16 | H24: =IF(G24<>"",0,F24) -> 6620.16
A25: Mar | B25: PPC/26652 | C25: TRAPICHE MINERACAO LTDA | D25: 1001002006 | E25: =_xlfn.XLOOKUP(D25,'Detalhamento - G200'!A:A,'Detalhamento - G200'!B:B,0) -> CONTENÇÕES | F25: 115500 | G25: CLSF/200-3-039 | H25: =IF(G25<>"",0,F25) -> 0
A26: Mar | B26: PPC/26680 | C26: TERRAM ENGENHARIA DE INFRAESTRUTURA LTDA | D26: 1001002003 | E26: =_xlfn.XLOOKUP(D26,'Detalhamento - G200'!A:A,'Detalhamento - G200'!B:B,0) -> MOVIMENTAÇÃO DE TERRA | F26: 2176885.7 | H26: =IF(G26<>"",0,F26) -> 2176885.7
A27: Mar | B27: PPC/26833 | C27: FORTPEL COMERCIO DE DESCARTAVEIS LTDA | D27: 2001008001 | E27: =_xlfn.XLOOKUP(D27,'Detalhamento - G200'!A:A,'Detalhamento - G200'!B:B,0) -> MATERIAIS DE COPA E LIMPEZA | F27: 1367.37 | H27: =IF(G27<>"",0,F27) -> 1367.37
A28: Mar | B28: PPC/26837 | C28: MARTINS E SILVA COMERCIO DE MERCADORIAS LTDA | D28: 2001008001 | E28: =_xlfn.XLOOKUP(D28,'Detalhamento - G200'!A:A,'Detalhamento - G200'!B:B,0) -> MATERIAIS DE COPA E LIMPEZA | F28: 3114.11 | H28: =IF(G28<>"",0,F28) -> 3114.11
A29: Mar | B29: PPC/26837 | C29: MARTINS E SILVA COMERCIO DE MERCADORIAS LTDA | D29: 1001006003 | E29: =_xlfn.XLOOKUP(D29,'Detalhamento - G200'!A:A,'Detalhamento - G200'!B:B,0) -> POÇO ARTESIANO | F29: 747 | H29: =IF(G29<>"",0,F29) -> 747
A30: Mar | B30: PPC/26877 | C30: CABOS E LAMPADAS COMERCIO DE MATERIAS ELETRICOS DE ALTA E BAIXA TENSAO EIRELI | D30: 2001001002 | E30: =_xlfn.XLOOKUP(D30,'Detalhamento - G200'!A:A,'Detalhamento - G200'!B:B,0) -> IMPLANTAÇÃO DE CANTEIRO - ELETRICA | F30: 183.06 | H30: =IF(G30<>"",0,F30) -> 183.06
A31: Mar | B31: PPC/26904 | C31: ELIZABETH CIMENTOS S/A | D31: 1001002006 | E31: =_xlfn.XLOOKUP(D31,'Detalhamento - G200'!A:A,'Detalhamento - G200'!B:B,0) -> CONTENÇÕES | F31: 115640 | G31: CLSF/200-3-039 | H31: =IF(G31<>"",0,F31) -> 0
A32: Mar | B32: PPC/26916 | C32: ALBERTO JOSE DOS SANTOS | D32: 2001004001 | E32: =_xlfn.XLOOKUP(D32,'Detalhamento - G200'!A:A,'Detalhamento - G200'!B:B,0) -> LOCAÇÃO DE MUNCK | F32: 8800 | H32: =IF(G32<>"",0,F32) -> 8800
A33: Mar | B33: PPC/26921 | C33: F & S MATERIAIS DE CONSTRUCAO EIRELI | D33: 2001001005 | E33: =_xlfn.XLOOKUP(D33,'Detalhamento - G200'!A:A,'Detalhamento - G200'!B:B,0) -> IMPLANTAÇÃO DE CANTEIRO - HIDRÁULICA | F33: 504.3 | H33: =IF(G33<>"",0,F33) -> 504.3
A34: Mar | B34: PPC/26922 | C34: A & A FERRAGEM LTDA | D34: 1002002001 | E34: =_xlfn.XLOOKUP(D34,'Detalhamento - G200'!A:A,'Detalhamento - G200'!B:B,0) -> FUNDAÇÃO | F34: 288 | H34: =IF(G34<>"",0,F34) -> 288
A35: Mar | B35: PPC/26925 | C35: TRANSPOL - DERIVADOS DE PETROLEO LTDA | D35: 1001002003 | E35: =_xlfn.XLOOKUP(D35,'Detalhamento - G200'!A:A,'Detalhamento - G200'!B:B,0) -> MOVIMENTAÇÃO DE TERRA | F35: 1380324.5 | G35: CLSF/200-3-015 | H35: =IF(G35<>"",0,F35) -> 0
A36: Mar | B36: PPC/26926 | C36: TRANSPORTADORA DE DIESEL CAVALO MARINHO LTDA | D36: 1001002003 | E36: =_xlfn.XLOOKUP(D36,'Detalhamento - G200'!A:A,'Detalhamento - G200'!B:B,0) -> MOVIMENTAÇÃO DE TERRA | F36: 1380324.5 | G36: CLSF/200-3-015 | H36: =IF(G36<>"",0,F36) -> 0
A37: Mar | B37: PPC/26929 | C37: PEDREIRAS CARANGI LTDA | D37: 1001002006 | E37: =_xlfn.XLOOKUP(D37,'Detalhamento - G200'!A:A,'Detalhamento - G200'!B:B,0) -> CONTENÇÕES | F37: 7920 | G37: CLSF/200-3-039 | H37: =IF(G37<>"",0,F37) -> 0
A38: Mar | B38: PPC/26929 | C38: PEDREIRAS CARANGI LTDA | D38: 1001002003 | E38: =_xlfn.XLOOKUP(D38,'Detalhamento - G200'!A:A,'Detalhamento - G200'!B:B,0) -> MOVIMENTAÇÃO DE TERRA | F38: 13580 | H38: =IF(G38<>"",0,F38) -> 13580
A39: Mar | B39: PPC/26929 | C39: PEDREIRAS CARANGI LTDA | D39: 1001002003 | E39: =_xlfn.XLOOKUP(D39,'Detalhamento - G200'!A:A,'Detalhamento - G200'!B:B,0) -> MOVIMENTAÇÃO DE TERRA | F39: 71780 | H39: =IF(G39<>"",0,F39) -> 71780
A40: Mar | B40: PPC/26936 | C40: PARATEC - PARA RAIOS E ACESSORIOS LTDA | D40: 1001003002 | E40: =_xlfn.XLOOKUP(D40,'Detalhamento - G200'!A:A,'Detalhamento - G200'!B:B,0) -> SUPERESTRUTURA GALPÃO | F40: 5933 | H40: =IF(G40<>"",0,F40) -> 5933
A41: Mar | B41: PPC/26949 | C41: LESSA EVENTOS LTDA | D41: 1001001002 | E41: =_xlfn.XLOOKUP(D41,'Detalhamento - G200'!A:A,'Detalhamento - G200'!B:B,0) -> ENSAIOS E CONSULTORIAS | F41: 680 | H41: =IF(G41<>"",0,F41) -> 680 | I41: LCL
A42: Mar | B42: PPC/26949 | C42: LESSA EVENTOS LTDA | D42: 1001002003 | E42: =_xlfn.XLOOKUP(D42,'Detalhamento - G200'!A:A,'Detalhamento - G200'!B:B,0) -> MOVIMENTAÇÃO DE TERRA | F42: 7035 | H42: =IF(G42<>"",0,F42) -> 7035 | I42: MAGALHÃES
A43: Mar | B43: PPC/26949 | C43: LESSA EVENTOS LTDA | D43: 1001001002 | E43: =_xlfn.XLOOKUP(D43,'Detalhamento - G200'!A:A,'Detalhamento - G200'!B:B,0) -> ENSAIOS E CONSULTORIAS | F43: 880 | H43: =IF(G43<>"",0,F43) -> 880 | I43: GEO2
...

Sheet Gestão de Contratos
B2: Instruções: | C2: No Sienge (Suprimentos / Contratos e Medições / Relatórios / Contratos / Faturamentos diretos);
C3: Obras 152/ Consultar / Gerar relatório excel;
B4: Observação: | C4: Esta planilha serva para a aba "analítico" não duplicar os custos, ou seja, para não associar as notas como uma nova contratação e estourar um saldo já contratado.
B13: CONTRATO | C13: CREDOR | D13: FATURAMENTO DIRETO | E13: FATURAMENTO CREDOR | F13: VRL. CONTRATO SIENGE | G13: VLR. CONTRATO JURÍDICO | H13: CHECK | I13: FATURADO CREDOR
B14: {=_xlfn.UNIQUE('Contratos - G200'!C14:C4990)} -> CLSF/200-3-000 | C14: {=_xlfn.XLOOKUP(B14,'Contratos - G200'!C:C,'Contratos - G200'!D:D,X)} -> QPC ENGENHARIA LTDA | D14: 0 | E14: 58566362 | F14: =SUMIF('Contratos - G200'!C:C,'Gestão de Contratos'!B14,'Contratos - G200'!J:J) -> 58566362 | G14: 58566362 | H14: =SUM(D14:E14)=F14 -> TRUE | I14: =SUMIF('Notas fiscais - G200'!W9:W4894,'Gestão de Contratos'!B14,'Notas fiscais - G200'!T9:T4894) -> 19685993
B15: CLSF/200-3-001 | C15: {=_xlfn.XLOOKUP(B15,'Contratos - G200'!C:C,'Contratos - G200'!D:D,X)} -> DPE ARQUITETURA E ENGENHARIA S/S | D15: 0 | E15: 450000 | F15: =SUMIF('Contratos - G200'!C:C,'Gestão de Contratos'!B15,'Contratos - G200'!J:J) -> 450000 | G15: 450000 | H15: =SUM(D15:E15)=F15 -> TRUE | I15: =SUMIF('Notas fiscais - G200'!W10:W4895,'Gestão de Contratos'!B15,'Notas fiscais - G200'!T10:T4895) -> 125400
B16: CLSF/200-3-002 | C16: {=_xlfn.XLOOKUP(B16,'Contratos - G200'!C:C,'Contratos - G200'!D:D,X)} -> ARQUITETURA JAPI PROJETOS E CONSULTORIA EIRELI | D16: 0 | E16: 472594.69 | F16: =SUMIF('Contratos - G200'!C:C,'Gestão de Contratos'!B16,'Contratos - G200'!J:J) -> 472594.69 | G16: 472594.69 | H16: =SUM(D16:E16)=F16 -> TRUE | I16: =SUMIF('Notas fiscais - G200'!W11:W4896,'Gestão de Contratos'!B16,'Notas fiscais - G200'!T11:T4896) -> 126368.28
B17: CLSF/200-3-003 | C17: {=_xlfn.XLOOKUP(B17,'Contratos - G200'!C:C,'Contratos - G200'!D:D,X)} -> DO VAL ENGENHARIA CONSULTIVA SOCIEDADE SIMPLES | D17: 0 | E17: 100000 | F17: =SUMIF('Contratos - G200'!C:C,'Gestão de Contratos'!B17,'Contratos - G200'!J:J) -> 100000 | G17: 100000 | H17: =SUM(D17:E17)=F17 -> TRUE | I17: =SUMIF('Notas fiscais - G200'!W12:W4897,'Gestão de Contratos'!B17,'Notas fiscais - G200'!T12:T4897) -> 0
B18: CLSF/200-3-004 | C18: {=_xlfn.XLOOKUP(B18,'Contratos - G200'!C:C,'Contratos - G200'!D:D,X)} -> LPE ENGENHARIA E CONSULTORIA LTDA | D18: 0 | E18: 244000 | F18: =SUMIF('Contratos - G200'!C:C,'Gestão de Contratos'!B18,'Contratos - G200'!J:J) -> 244000 | G18: 244000 | H18: =SUM(D18:E18)=F18 -> TRUE | I18: =SUMIF('Notas fiscais - G200'!W13:W4898,'Gestão de Contratos'!B18,'Notas fiscais - G200'!T13:T4898) -> 122000
B19: CLSF/200-3-005 | C19: {=_xlfn.XLOOKUP(B19,'Contratos - G200'!C:C,'Contratos - G200'!D:D,X)} -> T.T.C. ENGENHARIA DE TRAFEGO E DE TRANSPORTES LTDA | D19: 0 | E19: 9200 | F19: =SUMIF('Contratos - G200'!C:C,'Gestão de Contratos'!B19,'Contratos - G200'!J:J) -> 9200 | G19: 9200 | H19: =SUM(D19:E19)=F19 -> TRUE | I19: =SUMIF('Notas fiscais - G200'!W14:W4899,'Gestão de Contratos'!B19,'Notas fiscais - G200'!T14:T4899) -> 0
B20: CLSF/200-3-006 | C20: {=_xlfn.XLOOKUP(B20,'Contratos - G200'!C:C,'Contratos - G200'!D:D,X)} -> REV1 PROJETOS INTEGRADOS LTDA | D20: 0 | E20: 16917 | F20: =SUMIF('Contratos - G200'!C:C,'Gestão de Contratos'!B20,'Contratos - G200'!J:J) -> 16917 | G20: 16917 | H20: =SUM(D20:E20)=F20 -> TRUE | I20: =SUMIF('Notas fiscais - G200'!W15:W4900,'Gestão de Contratos'!B20,'Notas fiscais - G200'!T15:T4900) -> 10457.63
B21: CLSF/200-3-007 | C21: {=_xlfn.XLOOKUP(B21,'Contratos - G200'!C:C,'Contratos - G200'!D:D,X)} -> NUCLEORA PLANEJAMENTO, ASSESSORIA E DESENVOLVIMENTO COMERCIAL LTDA | D21: 0 | E21: 45000 | F21: =SUMIF('Contratos - G200'!C:C,'Gestão de Contratos'!B21,'Contratos - G200'!J:J) -> 45000 | G21: 45000 | H21: =SUM(D21:E21)=F21 -> TRUE | I21: =SUMIF('Notas fiscais - G200'!W16:W4901,'Gestão de Contratos'!B21,'Notas fiscais - G200'!T16:T4901) -> 13500
B22: CLSF/200-3-008 | C22: {=_xlfn.XLOOKUP(B22,'Contratos - G200'!C:C,'Contratos - G200'!D:D,X)} -> KAIZ ENGENHARIA LTDA | D22: 0 | E22: 64300 | F22: =SUMIF('Contratos - G200'!C:C,'Gestão de Contratos'!B22,'Contratos - G200'!J:J) -> 64300 | G22: 64300 | H22: =SUM(D22:E22)=F22 -> TRUE | I22: =SUMIF('Notas fiscais - G200'!W17:W4902,'Gestão de Contratos'!B22,'Notas fiscais - G200'!T17:T4902) -> 0
B23: CLSF/200-3-009 | C23: {=_xlfn.XLOOKUP(B23,'Contratos - G200'!C:C,'Contratos - G200'!D:D,X)} -> KAIZ ENGENHARIA LTDA | D23: 0 | E23: 68300 | F23: =SUMIF('Contratos - G200'!C:C,'Gestão de Contratos'!B23,'Contratos - G200'!J:J) -> 68300 | G23: 68300 | H23: =SUM(D23:E23)=F23 -> TRUE | I23: =SUMIF('Notas fiscais - G200'!W18:W4903,'Gestão de Contratos'!B23,'Notas fiscais - G200'!T18:T4903) -> 22220.27
B24: CLSF/200-3-010 | C24: {=_xlfn.XLOOKUP(B24,'Contratos - G200'!C:C,'Contratos - G200'!D:D,X)} -> VENDRAMINI ENGENHARIA LTDA | D24: 0 | E24: 0 | F24: =SUMIF('Contratos - G200'!C:C,'Gestão de Contratos'!B24,'Contratos - G200'!J:J) -> 0 | G24: 1316000 | H24: =SUM(D24:E24)=F24 -> TRUE | I24: =SUMIF('Notas fiscais - G200'!W19:W4904,'Gestão de Contratos'!B24,'Notas fiscais - G200'!T19:T4904) -> 275000
B25: CLSF/200-3-011 | C25: {=_xlfn.XLOOKUP(B25,'Contratos - G200'!C:C,'Contratos - G200'!D:D,X)} -> DO VAL ENGENHARIA CONSULTIVA SOCIEDADE SIMPLES | D25: 0 | E25: 87000 | F25: =SUMIF('Contratos - G200'!C:C,'Gestão de Contratos'!B25,'Contratos - G200'!J:J) -> 87000 | G25: 87000 | H25: =SUM(D25:E25)=F25 -> TRUE | I25: =SUMIF('Notas fiscais - G200'!W20:W4905,'Gestão de Contratos'!B25,'Notas fiscais - G200'!T20:T4905) -> 34800
B26: CLSF/200-3-012 | C26: {=_xlfn.XLOOKUP(B26,'Contratos - G200'!C:C,'Contratos - G200'!D:D,X)} -> GEOTECHNIQUE CONSULTORIA E ENGENHARIA LTDA | D26: 0 | E26: 250380 | F26: =SUMIF('Contratos - G200'!C:C,'Gestão de Contratos'!B26,'Contratos - G200'!J:J) -> 250380 | G26: 250380 | H26: =SUM(D26:E26)=F26 -> TRUE | I26: =SUMIF('Notas fiscais - G200'!W21:W4906,'Gestão de Contratos'!B26,'Notas fiscais - G200'!T21:T4906) -> 0
... B32: CLSF/200-3-018 | C32: {=_xlfn.XLOOKUP(B32,'Contratos - G200'!C:C,'Contratos - G200'!D:D,X)} -> FF INFRA E ENGENHARIA LTDA | D32: 221200 | E32: 94800 | F32: =SUMIF('Contratos - G200'!C:C,'Gestão de Contratos'!B32,'Contratos - G200'!J:J) -> 316000 | G32: 316000 | H32: =SUM(D32:E32)=F32 -> TRUE | I32: =SUMIF('Notas fiscais - G200'!W27:W4912,'Gestão de Contratos'!B32,'Notas fiscais - G200'!T27:T4912) -> 46728.1
B33: CLSF/200-3-019 | C33: {=_xlfn.XLOOKUP(B33,'Contratos - G200'!C:C,'Contratos - G200'!D:D,X)} -> AQUAGEO PROJETOS E PERFURACOES LTDA | D33: 0 | E33: =286456.27-66003.27 -> 220453 | F33: =SUMIF('Contratos - G200'!C:C,'Gestão de Contratos'!B33,'Contratos - G200'!J:J) -> 286456.27 | G33: 286456.27 | H33: =SUM(D33:E33)=F33 -> FALSE | I33: =SUMIF('Notas fiscais - G200'!W28:W4913,'Gestão de Contratos'!B33,'Notas fiscais - G200'!T28:T4913) -> 136066.73
B34: CLSF/200-3-020 | C34: {=_xlfn.XLOOKUP(B34,'Contratos - G200'!C:C,'Contratos - G200'!D:D,X)} -> SPM ENGENHARIA SOCIEDADE SIMPLES LTDA. | D34: 0 | E34: 0 | F34: =SUMIF('Contratos - G200'!C:C,'Gestão de Contratos'!B34,'Contratos - G200'!J:J) -> 0 | G34: 568700 | H34: =SUM(D34:E34)=F34 -> TRUE | I34: =SUMIF('Notas fiscais - G200'!W29:W4914,'Gestão de Contratos'!B34,'Notas fiscais - G200'!T29:T4914) -> 142175
B35: CLSF/200-3-021 | C35: {=_xlfn.XLOOKUP(B35,'Contratos - G200'!C:C,'Contratos - G200'!D:D,X)} -> LAEROMEC - SOLUCOES EM ENGENHARIA LTDA | D35: 0 | E35: 0 | F35: =SUMIF('Contratos - G200'!C:C,'Gestão de Contratos'!B35,'Contratos - G200'!J:J) -> 0 | G35: 31300 | H35: =SUM(D35:E35)=F35 -> TRUE | I35: =SUMIF('Notas fiscais - G200'!W30:W4915,'Gestão de Contratos'!B35,'Notas fiscais - G200'!T30:T4915) -> 15650
B36: CLSF/200-3-022 | C36: {=_xlfn.XLOOKUP(B36,'Contratos - G200'!C:C,'Contratos - G200'!D:D,X)} -> SOLOBAHIA ENGENHARIA E TECNOLOGIA LTDA | D36: 0 | E36: 141411.45 | F36: =SUMIF('Contratos - G200'!C:C,'Gestão de Contratos'!B36,'Contratos - G200'!J:J) -> 141411.45 | G36: 141411.45 | H36: =SUM(D36:E36)=F36 -> TRUE | I36: =SUMIF('Notas fiscais - G200'!W31:W4916,'Gestão de Contratos'!B36,'Notas fiscais - G200'!T31:T4916) -> 37451.69
B37: CLSF/200-3-023 | C37: {=_xlfn.XLOOKUP(B37,'Contratos - G200'!C:C,'Contratos - G200'!D:D,X)} -> LESSA EVENTOS LTDA | D37: 0 | E37: 1808700.4 | F37: =SUMIF('Contratos - G200'!C:C,'Gestão de Contratos'!B37,'Contratos - G200'!J:J) -> 1808700.4 | G37: 1808700.4 | H37: =SUM(D37:E37)=F37 -> TRUE | I37: =SUMIF('Notas fiscais - G200'!W32:W4917,'Gestão de Contratos'!B37,'Notas fiscais - G200'!T32:T4917) -> 75495.05
B38: CLSF/200-3-024 | C38: {=_xlfn.XLOOKUP(B38,'Contratos - G200'!C:C,'Contratos - G200'!D:D,X)} -> BOME EMPREENDIMENTOS E SERVICOS LTDA | D38: 0 | E38: 1304518.2 | F38: =SUMIF('Contratos - G200'!C:C,'Gestão de Contratos'!B38,'Contratos - G200'!J:J) -> 1304518.2 | G38: 1304518.2 | H38: =SUM(D38:E38)=F38 -> TRUE | I38: =SUMIF('Notas fiscais - G200'!W33:W4918,'Gestão de Contratos'!B38,'Notas fiscais - G200'!T33:T4918) -> 58979.88
B39: CLSF/200-3-025 | C39: {=_xlfn.XLOOKUP(B39,'Contratos - G200'!C:C,'Contratos - G200'!D:D,X)} -> LEONARDO SANTOS GONCALVES PRODUCAO E SOLUCOES EM VIDEOS | D39: 0 | E39: 32200 | F39: =SUMIF('Contratos - G200'!C:C,'Gestão de Contratos'!B39,'Contratos - G200'!J:J) -> 32200 | G39: 32200 | H39: =SUM(D39:E39)=F39 -> TRUE | I39: =SUMIF('Notas fiscais - G200'!W34:W4919,'Gestão de Contratos'!B39,'Notas fiscais - G200'!T34:T4919) -> 4600
B40: CLSF/200-3-026 | C40: {=_xlfn.XLOOKUP(B40,'Contratos - G200'!C:C,'Contratos - G200'!D:D,X)} -> SOFTCOMP COMERCIO SERVICOS TELECOMUNICACOES E INFORMATICA EIRELI | D40: 0 | E40: 43750 | F40: =SUMIF('Contratos - G200'!C:C,'Gestão de Contratos'!B40,'Contratos - G200'!J:J) -> 43750 | G40: 43750 | H40: =SUM(D40:E40)=F40 -> TRUE | I40: =SUMIF('Notas fiscais - G200'!W35:W4920,'Gestão de Contratos'!B40,'Notas fiscais - G200'!T35:T4920) -> 4200
B41: CLSF/200-3-027 | C41: {=_xlfn.XLOOKUP(B41,'Contratos - G200'!C:C,'Contratos - G200'!D:D,X)} -> AMARAL GERENCIAMENTO DE RESIDUOS LTDA | D41: 0 | E41: 163230 | F41: =SUMIF('Contratos - G200'!C:C,'Gestão de Contratos'!B41,'Contratos - G200'!J:J) -> 163230 | G41: 163230 | H41: =SUM(D41:E41)=F41 -> TRUE | I41: =SUMIF('Notas fiscais - G200'!W36:W4921,'Gestão de Contratos'!B41,'Notas fiscais - G200'!T36:T4921) -> 6280
B42: CLSF/200-3-028 | C42: {=_xlfn.XLOOKUP(B42,'Contratos - G200'!C:C,'Contratos - G200'!D:D,X)} -> BIOFUTURO ENGENHARIA E SOLUCOES AMBIENTAIS EIRELI | D42: 864100 | E42: =350000+63900 -> 413900 | F42: =SUMIF('Contratos - G200'!C:C,'Gestão de Contratos'!B42,'Contratos - G200'!J:J) -> 1278000 | G42: 1278000 | H42: =SUM(D42:E42)=F42 -> TRUE | I42: =SUMIF('Notas fiscais - G200'!W37:W4922,'Gestão de Contratos'!B42,'Notas fiscais - G200'!T37:T4922) -> 350000
B43: CLSF/200-3-029 | C43: {=_xlfn.XLOOKUP(B43,'Contratos - G200'!C:C,'Contratos - G200'!D:D,X)} -> TRANSDADOS INTERNET LTDA | D43: 0 | E43: 11200 | F43: =SUMIF('Contratos - G200'!C:C,'Gestão de Contratos'!B43,'Contratos - G200'!J:J) -> 11200 | G43: 11200 | H43: =SUM(D43:E43)=F43 -> TRUE | I43: =SUMIF('Notas fiscais - G200'!W38:W4923,'Gestão de Contratos'!B43,'Notas fiscais - G200'!T38:T4923) -> 800
B44: CLSF/200-3-030 | C44: {=_xlfn.XLOOKUP(B44,'Contratos - G200'!C:C,'Contratos - G200'!D:D,X)} -> LC ADIA - LOCACAO DE VEICULOS LTDA | D44: 0 | E44: 1895760 | F44: =SUMIF('Contratos - G200'!C:C,'Gestão de Contratos'!B44,'Contratos - G200'!J:J) -> 1895760 | G44: 1895760 | H44: =SUM(D44:E44)=F44 -> TRUE | I44: =SUMIF('Notas fiscais - G200'!W39:W4924,'Gestão de Contratos'!B44,'Notas fiscais - G200'!T39:T4924) -> 46165.38
B45: CLSF/200-3-031 | C45: {=_xlfn.XLOOKUP(B45,'Contratos - G200'!C:C,'Contratos - G200'!D:D,X)} -> KOPRON DO BRASIL COMERCIO E INDUSTRIA DE EQUIPAMENTOS DE LOGISTICA LTDA | D45: 337100 | E45: 3262900 | F45: =SUMIF('Contratos - G200'!C:C,'Gestão de Contratos'!B45,'Contratos - G200'!J:J) -> 3600000 | G45: 3600000 | H45: =SUM(D45:E45)=F45 -> TRUE | I45: =SUMIF('Notas fiscais - G200'!W40:W4925,'Gestão de Contratos'!B45,'Notas fiscais - G200'!T40:T4925) -> 2760469.1
B46: CLSF/200-3-032 | C46: {=_xlfn.XLOOKUP(B46,'Contratos - G200'!C:C,'Contratos - G200'!D:D,X)} -> ROTULA METALURGICA LTDA | D46: =10410893.24+5363187.43 -> 15774081 | E46: =26365249.11+2929472.13 -> 29294721 | F46: =SUMIF('Contratos - G200'!C:C,'Gestão de Contratos'!B46,'Contratos - G200'!J:J) -> 45068802 | G46: 45068802 | H46: =SUM(D46:E46)=F46 -> TRUE | I46: =SUMIF('Notas fiscais - G200'!W41:W4926,'Gestão de Contratos'!B46,'Notas fiscais - G200'!T41:T4926) -> 18027521
B47: CLSF/200-3-033 | C47: {=_xlfn.XLOOKUP(B47,'Contratos - G200'!C:C,'Contratos - G200'!D:D,X)} -> T & A CONSTRUCAO PRE-FABRICADA S/A | D47: =55318464.52+13107641.16 -> 68426106 | E47: =3175000+7790000+1312000 -> 12277000 | F47: =SUMIF('Contratos - G200'!C:C,'Gestão de Contratos'!B47,'Contratos - G200'!J:J) -> 80703106 | G47: 80703106 | H47: =SUM(D47:E47)=F47 -> FALSE | I47: =SUMIF('Notas fiscais - G200'!W42:W4927,'Gestão de Contratos'!B47,'Notas fiscais - G200'!T42:T4927) -> 21742126
B48: CLSF/200-3-034 | C48: {=_xlfn.XLOOKUP(B48,'Contratos - G200'!C:C,'Contratos - G200'!D:D,X)} -> ARTEMP ENGENHARIA DE INSTALAÇÕES LTDA | D48: 23500000 | E48: 25916467 | F48: =SUMIF('Contratos - G200'!C:C,'Gestão de Contratos'!B48,'Contratos - G200'!J:J) -> 49416467 | G48: 49416467 | H48: =SUM(D48:E48)=F48 -> TRUE | I48: =SUMIF('Notas fiscais - G200'!W43:W4928,'Gestão de Contratos'!B48,'Notas fiscais - G200'!T43:T4928) -> 15093475
B49: CLSF/200-3-035 | C49: {=_xlfn.XLOOKUP(B49,'Contratos - G200'!C:C,'Contratos - G200'!D:D,X)} -> ENTEL COMERCIO E SERVICOS LTDA | D49: 0 | E49: 28020 | F49: =SUMIF('Contratos - G200'!C:C,'Gestão de Contratos'!B49,'Contratos - G200'!J:J) -> 28020 | G49: 28020 | H49: =SUM(D49:E49)=F49 -> TRUE | I49: =SUMIF('Notas fiscais - G200'!W44:W4929,'Gestão de Contratos'!B49,'Notas fiscais - G200'!T44:T4929) -> 3622.6
B50: CLSF/200-3-036 | C50: {=_xlfn.XLOOKUP(B50,'Contratos - G200'!C:C,'Contratos - G200'!D:D,X)} -> THYSSENKRUPP ELEVADORES AS | D50: 0 | E50: 171000 | F50: =SUMIF('Contratos - G200'!C:C,'Gestão de Contratos'!B50,'Contratos - G200'!J:J) -> 171000 | G50: 171000 | H50: =SUM(D50:E50)=F50 -> TRUE | I50: =SUMIF('Notas fiscais - G200'!W45:W4930,'Gestão de Contratos'!B50,'Notas fiscais - G200'!T45:T4930) -> 43605
B51: CLSF/200-3-037 | C51: {=_xlfn.XLOOKUP(B51,'Contratos - G200'!C:C,'Contratos - G200'!D:D,X)} -> KAIZ ENGENHARIA LTDA | D51: 0 | E51: 38000 | F51: =SUMIF('Contratos - G200'!C:C,'Gestão de Contratos'!B51,'Contratos - G200'!J:J) -> 38000 | G51: 38000 | H51: =SUM(D51:E51)=F51 -> TRUE | I51: =SUMIF('Notas fiscais - G200'!W46:W4931,'Gestão de Contratos'!B51,'Notas fiscais - G200'!T46:T4931) -> 0
B52: CLSF/200-3-038 | C52: {=_xlfn.XLOOKUP(B52,'Contratos - G200'!C:C,'Contratos - G200'!D:D,X)} -> SOTEC FABRICACAO DE ESTRUTURAS METALICAS E SERVICOS LTDA | D52: 2000000.4 | E52: 500000.09 | F52: =SUMIF('Contratos - G200'!C:C,'Gestão de Contratos'!B52,'Contratos - G200'!J:J) -> 2500000.5 | G52: 2500000.5 | H52: =SUM(D52:E52)=F52 -> TRUE | I52: =SUMIF('Notas fiscais - G200'!W47:W4932,'Gestão de Contratos'!B52,'Notas fiscais - G200'!T47:T4932) -> 500000.09
B53: CLSF/200-3-039 | C53: {=_xlfn.XLOOKUP(B53,'Contratos - G200'!C:C,'Contratos - G200'!D:D,X)} -> VOC ENGENHARIA E CONSTRUCAO LTDA | D53: 3464956.6 | E53: 1968054.6 | F53: =SUMIF('Contratos - G200'!C:C,'Gestão de Contratos'!B53,'Contratos - G200'!J:J) -> 5433011.2 | G53: 5433011.2 | H53: =SUM(D53:E53)=F53 -> FALSE | I53: =SUMIF('Notas fiscais - G200'!W48:W4933,'Gestão de Contratos'!B53,'Notas fiscais - G200'!T48:T4933) -> 1245656.5
B54: CLSF/200-3-040 | C54: {=_xlfn.XLOOKUP(B54,'Contratos - G200'!C:C,'Contratos - G200'!D:D,X)} -> GEOTECHNIQUE CONSULTORIA E ENGENHARIA LTDA | D54: 0 | E54: 175000 | F54: =SUMIF('Contratos - G200'!C:C,'Gestão de Contratos'!B54,'Contratos - G200'!J:J) -> 175000 | G54: 175000 | H54: =SUM(D54:E54)=F54 -> TRUE | I54: =SUMIF('Notas fiscais - G200'!W49:W4934,'Gestão de Contratos'!B54,'Notas fiscais - G200'!T49:T4934) -> 0
...

Sheet Contratos - G200
C2: Instruções: | D2: No Sienge (Suprimentos / Contratos e Medições / Relatórios / Contratos / Faturamentos diretos); | I2: No Sienge (Suprimentos / Contratos e Medições / Relatórios / Contratos / Faturamentos diretos);
D3: Obras 152/ Consultar / Gerar relatório excel; | I3: Obras 152/ Consultar / Gerar relatório excel;
C4: Observação: | D4: Esta planilha serva para a aba "analítico" não duplicar os custos, ou seja, para não associar as notas como uma nova contratação e estourar um saldo já contratado. | I4: Esta planilha serva para a aba "analítico" não duplicar os custos, ou seja, para não associar as notas como uma nova contratação e estourar um saldo já contratado.
E11: TOTAL | G11: =SUBTOTAL(9,G14:G1048576) -> 3.263279e+08 | I11: =G11-J11 -> 2141000 | J11: =SUBTOTAL(9,J14:J1048576) -> 3.241869e+08
C13: CONTRATO | D13: CREDOR | E13: APROPRIAÇÃO | F13: DESCRIÇÃO DA EAP | G13: VALOR | H13: ESCOPO DO CONTRATO | I13: VÍNCULO DE FATURAMENTO DIRETO | J13: VALOR À CONSIDERAR
B14: CT-LSFG200-000 | C14: CLSF/200-3-000 | D14: QPC ENGENHARIA LTDA | E14: 2001025001 | F14: =_xlfn.XLOOKUP(E14,'Detalhamento - G200'!A:A,'Detalhamento - G200'!B:B,0) -> DESPESAS INDIRETAS DE OBRA, CANTEIRO, INSTALAÇÕES PROVISÓRIAS - FATURAMENTO QPC | G14: 2000000 | H14: EXECUÇÃO DO PMG | J14: =IF(I14<>"",0,G14) -> 2000000
B15: CT-LSFG200-000 | C15: CLSF/200-3-000 | D15: QPC ENGENHARIA LTDA | E15: 2001025002 | F15: =_xlfn.XLOOKUP(E15,'Detalhamento - G200'!A:A,'Detalhamento - G200'!B:B,0) -> DESPESAS INDIRETAS DE OBRA - DESEMBOLSO CANTEIRO DE OBRAS | G15: 300000 | H15: EXECUÇÃO DO PMG | J15: =IF(I15<>"",0,G15) -> 300000
B16: CT-LSFG200-000 | C16: CLSF/200-3-000 | D16: QPC ENGENHARIA LTDA | E16: 2002001001 | F16: =_xlfn.XLOOKUP(E16,'Detalhamento - G200'!A:A,'Detalhamento - G200'!B:B,0) -> SALÁRIOS, DISSÍDIO/REAJUSTE E AJUDA DE CUSTO | G16: 19609894 | H16: EXECUÇÃO DO PMG | J16: =IF(I16<>"",0,G16) -> 19609894
B17: CT-LSFG200-000 | C17: CLSF/200-3-000 | D17: QPC ENGENHARIA LTDA | E17: 2003001001 | F17: =_xlfn.XLOOKUP(E17,'Detalhamento - G200'!A:A,'Detalhamento - G200'!B:B,0) -> FEE | G17: 36656469 | H17: EXECUÇÃO DO PMG | J17: =IF(I17<>"",0,G17) -> 36656469
B18: CT-LSFG200-001 | C18: CLSF/200-3-001 | D18: DPE ARQUITETURA E ENGENHARIA S/S | E18: 1001001001 | F18: =_xlfn.XLOOKUP(E18,'Detalhamento - G200'!A:A,'Detalhamento - G200'!B:B,0) -> PROJETOS | G18: 450000 | H18: PROJETO DE INSTALAÇÕES | J18: =IF(I18<>"",0,G18) -> 450000
B19: CT-LSFG200-002 | C19: CLSF/200-3-002 | D19: ARQUITETURA JAPI PROJETOS E CONSULTORIA EIRELI | E19: 1001001001 | F19: =_xlfn.XLOOKUP(E19,'Detalhamento - G200'!A:A,'Detalhamento - G200'!B:B,0) -> PROJETOS | G19: 472594.69 | H19: PROJETO DE ARQUITETURA | J19: =IF(I19<>"",0,G19) -> 472594.69
B20: CT-LSFG200-003 | C20: CLSF/200-3-003 | D20: DO VAL ENGENHARIA CONSULTIVA SOCIEDADE SIMPLES | E20: 1001001001 | F20: =_xlfn.XLOOKUP(E20,'Detalhamento - G200'!A:A,'Detalhamento - G200'!B:B,0) -> PROJETOS | G20: 100000 | H20: CQP FUNDAÇÃO E CONTENÇÃO | J20: =IF(I20<>"",0,G20) -> 100000
B21: CT-LSFG200-004 | C21: CLSF/200-3-004 | D21: LPE ENGENHARIA E CONSULTORIA LTDA | E21: 1001001001 | F21: =_xlfn.XLOOKUP(E21,'Detalhamento - G200'!A:A,'Detalhamento - G200'!B:B,0) -> PROJETOS | G21: 244000 | H21: PROJETO DE PISO DE CONCRETO | J21: =IF(I21<>"",0,G21) -> 244000
B22: CT-LSFG200-005 | C22: CLSF/200-3-005 | D22: T.T.C. ENGENHARIA DE TRAFEGO E DE TRANSPORTES LTDA | E22: 1001001001 | F22: =_xlfn.XLOOKUP(E22,'Detalhamento - G200'!A:A,'Detalhamento - G200'!B:B,0) -> PROJETOS | G22: 9200 | H22: PROJETO DE SINALIZAÇÃO VIÁRIA | J22: =IF(I22<>"",0,G22) -> 9200
B23: CT-LSFG200-006 | C23: CLSF/200-3-006 | D23: REV1 PROJETOS INTEGRADOS LTDA | E23: 1001001001 | F23: =_xlfn.XLOOKUP(E23,'Detalhamento - G200'!A:A,'Detalhamento - G200'!B:B,0) -> PROJETOS | G23: 16917 | H23: PROJETO DE EPC | J23: =IF(I23<>"",0,G23) -> 16917
B24: CT-LSFG200-007 | C24: CLSF/200-3-007 | D24: NUCLEORA PLANEJAMENTO, ASSESSORIA E DESENVOLVIMENTO COMERCIAL LTDA | E24: 1001001001 | F24: =_xlfn.XLOOKUP(E24,'Detalhamento - G200'!A:A,'Detalhamento - G200'!B:B,0) -> PROJETOS | G24: 45000 | H24: PROJETO DE COZINHA INDUSTRIAL | J24: =IF(I24<>"",0,G24) -> 45000
B25: CT-LSFG200-008 | C25: CLSF/200-3-008 | D25: KAIZ ENGENHARIA LTDA | E25: 1001001001 | F25: =_xlfn.XLOOKUP(E25,'Detalhamento - G200'!A:A,'Detalhamento - G200'!B:B,0) -> PROJETOS | G25: 64300 | H25: CQP PRÉ FABRICADO | J25: =IF(I25<>"",0,G25) -> 64300
B26: CT-LSFG200-009 | C26: CLSF/200-3-009 | D26: KAIZ ENGENHARIA LTDA | E26: 1001001001 | F26: =_xlfn.XLOOKUP(E26,'Detalhamento - G200'!A:A,'Detalhamento - G200'!B:B,0) -> PROJETOS | G26: 68300 | H26: PROJETOS ESTRUTURAS DE CONCRETO (IN-LOCO) E ALVENARIAS | J26: =IF(I26<>"",0,G26) -> 68300
B27: CT-LSFG200-010 | C27: CLSF/200-3-010 | D27: VENDRAMINI ENGENHARIA LTDA | E27: 1001003001 | F27: =_xlfn.XLOOKUP(E27,'Detalhamento - G200'!A:A,'Detalhamento - G200'!B:B,0) -> FUNDAÇÃO GALPÃO | G27: 1117668.8 | H27: PROJETO DE ESTRUTURAS PRÉ-FABRICADAS DE CONCRETO | I27: CLSF/200-3-033 | J27: =IF(I27<>"",0,G27) -> 0
B28: CT-LSFG200-010 | C28: CLSF/200-3-010 | D28: VENDRAMINI ENGENHARIA LTDA | E28: 1001003002 | F28: =_xlfn.XLOOKUP(E28,'Detalhamento - G200'!A:A,'Detalhamento - G200'!B:B,0) -> SUPERESTRUTURA GALPÃO | G28: 41644.8 | H28: PROJETO DE ESTRUTURAS PRÉ-FABRICADAS DE CONCRETO | I28: CLSF/200-3-033 | J28: =IF(I28<>"",0,G28) -> 0
B29: CT-LSFG200-010 | C29: CLSF/200-3-010 | D29: VENDRAMINI ENGENHARIA LTDA | E29: 1002002002 | F29: =_xlfn.XLOOKUP(E29,'Detalhamento - G200'!A:A,'Detalhamento - G200'!B:B,0) -> SUPERESTRUTURA | G29: 156686.4 | H29: PROJETO DE ESTRUTURAS PRÉ-FABRICADAS DE CONCRETO | I29: CLSF/200-3-033 | J29: =IF(I29<>"",0,G29) -> 0
B30: CT-LSFG200-011 | C30: CLSF/200-3-011 | D30: DO VAL ENGENHARIA CONSULTIVA SOCIEDADE SIMPLES | E30: 1001001001 | F30: =_xlfn.XLOOKUP(E30,'Detalhamento - G200'!A:A,'Detalhamento - G200'!B:B,0) -> PROJETOS | G30: 87000 | H30: PROJETO DE FUNDAÇÃO PROFUNDA - GALPÃO | J30: =IF(I30<>"",0,G30) -> 87000
B31: CT-LSFG200-012 | C31: CLSF/200-3-012 | D31: GEOTECHNIQUE CONSULTORIA E ENGENHARIA LTDA | E31: 1001001001 | F31: =_xlfn.XLOOKUP(E31,'Detalhamento - G200'!A:A,'Detalhamento - G200'!B:B,0) -> PROJETOS | G31: 250380 | H31: PROJETO DE TERRAPLANAGEM / FUNDAÇÃO/ DRENAGEM / CONTENÇÃO | J31: =IF(I31<>"",0,G31) -> 250380
B32: CT-LSFG200-013 | C32: CLSF/200-3-013 | D32: VENDRAMINI ENGENHARIA LTDA | E32: 1001001001 | F32: =_xlfn.XLOOKUP(E32,'Detalhamento - G200'!A:A,'Detalhamento - G200'!B:B,0) -> PROJETOS | G32: 153000 | H32: CQP METÁLICA | J32: =IF(I32<>"",0,G32) -> 153000
B33: CT-LSFG200-014 | C33: CLSF/200-3-014 | D33: LCL GEOTECNIA E SONDAGEM LTDA | E33: 1001001002 | F33: =_xlfn.XLOOKUP(E33,'Detalhamento - G200'!A:A,'Detalhamento - G200'!B:B,0) -> ENSAIOS E CONSULTORIAS | G33: 919769.9 | H33: CONTROLE TECNOLÓGICO DE SOLOS | J33: =IF(I33<>"",0,G33) -> 919769.9
B34: CT-LSFG200-015 | C34: CLSF/200-3-015 | D34: MAGALHAES JUNIOR LOCACAO E SERVICOS LTDA | E34: 1001002003 | F34: =_xlfn.XLOOKUP(E34,'Detalhamento - G200'!A:A,'Detalhamento - G200'!B:B,0) -> MOVIMENTAÇÃO DE TERRA | G34: 18314788 | H34: TERRAPLENAGEM | J34: =IF(I34<>"",0,G34) -> 18314788
B35: CT-LSFG200-015 | C35: CLSF/200-3-015 | D35: MAGALHAES JUNIOR LOCACAO E SERVICOS LTDA | E35: 1001002007 | F35: =_xlfn.XLOOKUP(E35,'Detalhamento - G200'!A:A,'Detalhamento - G200'!B:B,0) -> ESCAVAÇÃO NO TARDOZ | G35: 800400.01 | H35: TERRAPLENAGEM | J35: =IF(I35<>"",0,G35) -> 800400.01
B36: CT-LSFG200-016 | C36: CLSF/200-3-016 | D36: GEO2 ENGENHARIA LTDA | E36: 1001001002 | F36: =_xlfn.XLOOKUP(E36,'Detalhamento - G200'!A:A,'Detalhamento - G200'!B:B,0) -> ENSAIOS E CONSULTORIAS | G36: 732314.04 | H36: TOPOGRAFIA | J36: =IF(I36<>"",0,G36) -> 732314.04
B37: CT-LSFG200-017 | C37: CLSF/200-3-017 | D37: QUALYSAN LOCACAO DE BENS MOVEIS EIRELI | E37: 2001013001 | F37: =_xlfn.XLOOKUP(E37,'Detalhamento - G200'!A:A,'Detalhamento - G200'!B:B,0) -> LOCAÇÃO - SANITÁRIO QUÍMICO | G37: 89600 | H37: LOCAÇÃO DE BANHEIRO QUÍMICO | J37: =IF(I37<>"",0,G37) -> 89600
B38: CT-LSFG200-018 | C38: CLSF/200-3-018 | D38: FF INFRA E ENGENHARIA LTDA | E38: 2001001002 | F38: =_xlfn.XLOOKUP(E38,'Detalhamento - G200'!A:A,'Detalhamento - G200'!B:B,0) -> IMPLANTAÇÃO DE CANTEIRO - ELETRICA | G38: 316000 | H38: LIGAÇÃO DE ENERGIA PROVISÓRIA | J38: =IF(I38<>"",0,G38) -> 316000
B39: CT-LSFG200-019 | C39: CLSF/200-3-019 | D39: AQUAGEO PROJETOS E PERFURACOES LTDA | E39: 1001006003 | F39: =_xlfn.XLOOKUP(E39,'Detalhamento - G200'!A:A,'Detalhamento - G200'!B:B,0) -> POÇO ARTESIANO | G39: 286456.27 | H39: POÇO ARTESIANO | J39: =IF(I39<>"",0,G39) -> 286456.27
B40: CT-LSFG200-020 | C40: CLSF/200-3-020 | D40: SPM ENGENHARIA SOCIEDADE SIMPLES LTDA. | E40: 1003006001 | F40: =_xlfn.XLOOKUP(E40,'Detalhamento - G200'!A:A,'Detalhamento - G200'!B:B,0) -> PROJETOS, CQPS E AS BUILT | G40: 568700 | H40: ELABORAÇÃO DE PROJETO(S) PARA INSTALAÇÕES DE HVAC | I40: CLSF/200-3-042 | J40: =IF(I40<>"",0,G40) -> 0
B41: CT-LSFG200-021 | C41: CLSF/200-3-021 | D41: LAEROMEC - SOLUCOES EM ENGENHARIA LTDA | E41: 1003006001 | F41: =_xlfn.XLOOKUP(E41,'Detalhamento - G200'!A:A,'Detalhamento - G200'!B:B,0) -> PROJETOS, CQPS E AS BUILT | G41: 31300 | H41: ANÁLISE DINÂMICA DOS FLUIDOS COMPUTACIONAL DO PROJETO DE HVAC | I41: CLSF/200-3-042 | J41: =IF(I41<>"",0,G41) -> 0
B42: CT-LSFG200-022 | C42: CLSF/200-3-022 | D42: SOLOBAHIA ENGENHARIA E TECNOLOGIA LTDA | E42: 1001001002 | F42: =_xlfn.XLOOKUP(E42,'Detalhamento - G200'!A:A,'Detalhamento - G200'!B:B,0) -> ENSAIOS E CONSULTORIAS | G42: 141411.45 | H42: SONDAGENS | J42: =IF(I42<>"",0,G42) -> 141411.45
B43: CT-LSFG200-023 | C43: CLSF/200-3-023 | D43: LESSA EVENTOS LTDA | E43: 1001002003 | F43: =_xlfn.XLOOKUP(E43,'Detalhamento - G200'!A:A,'Detalhamento - G200'!B:B,0) -> MOVIMENTAÇÃO DE TERRA | G43: 9586.11 | H43: ALIMENTAÇÃO | J43: =IF(I43<>"",0,G43) -> 9586.11
B44: CT-LSFG200-023 | C44: CLSF/200-3-023 | D44: LESSA EVENTOS LTDA | E44: 1001002006 | F44: =_xlfn.XLOOKUP(E44,'Detalhamento - G200'!A:A,'Detalhamento - G200'!B:B,0) -> CONTENÇÕES | G44: 142887.34 | H44: ALIMENTAÇÃO | J44: =IF(I44<>"",0,G44) -> 142887.34
B45: CT-LSFG200-023 | C45: CLSF/200-3-023 | D45: LESSA EVENTOS LTDA | E45: 1001002008 | F45: =_xlfn.XLOOKUP(E45,'Detalhamento - G200'!A:A,'Detalhamento - G200'!B:B,0) -> DRENAGEM | G45: 190998.76 | H45: ALIMENTAÇÃO | J45: =IF(I45<>"",0,G45) -> 190998.76
B46: CT-LSFG200-023 | C46: CLSF/200-3-023 | D46: LESSA EVENTOS LTDA | E46: 1001003001 | F46: =_xlfn.XLOOKUP(E46,'Detalhamento - G200'!A:A,'Detalhamento - G200'!B:B,0) -> FUNDAÇÃO GALPÃO | G46: 75422.81 | H46: ALIMENTAÇÃO | J46: =IF(I46<>"",0,G46) -> 75422.81
B47: CT-LSFG200-023 | C47: CLSF/200-3-023 | D47: LESSA EVENTOS LTDA | E47: 1001003002 | F47: =_xlfn.XLOOKUP(E47,'Detalhamento - G200'!A:A,'Detalhamento - G200'!B:B,0) -> SUPERESTRUTURA GALPÃO | G47: 4702.62 | H47: ALIMENTAÇÃO | J47: =IF(I47<>"",0,G47) -> 4702.62
B48: CT-LSFG200-023 | C48: CLSF/200-3-023 | D48: LESSA EVENTOS LTDA | E48: 1001003006 | F48: =_xlfn.XLOOKUP(E48,'Detalhamento - G200'!A:A,'Detalhamento - G200'!B:B,0) -> IMPERMEABILIZAÇÃO | G48: 16640.04 | H48: ALIMENTAÇÃO | J48: =IF(I48<>"",0,G48) -> 16640.04
...

Sheet Projeções - G200
C2: OBRA | D2: G200
C3: INÍCIO
C4: TÉRMINO
C5: RESPONSÁVEL | D5: SÉRGIO COSTA
C7: TOTAIS | D7: =SUM(D10:D201) -> 0 | F7: =SUM(F10:F201) -> -267155.08
D8: =D7='Detalhamento - G200'!G6 -> FALSE | E8: ATUALIZAR AQUI | F8: =F7='Detalhamento - G200'!I6 -> TRUE
B9: APROPRIAÇÃO | C9: DESCRIÇÃO | D9: SALDO | E9: PREVISÃO | F9: PROJEÇÕES | G9: OBSERVAÇÃO
B10: =_xlfn.XLOOKUP(C10,'Detalhamento - G200'!B6:B253,'Detalhamento - G200'!A6:A253,0) -> 1001001001 | C10: PROJETOS | D10: =VLOOKUP(B10,'Detalhamento - G200'!A:G,5,) -> 0 | F10: =D10+E10 -> 0
B11: =_xlfn.XLOOKUP(C11,'Detalhamento - G200'!B7:B254,'Detalhamento - G200'!A7:A254,0) -> 1001001002 | C11: ENSAIOS E CONSULTORIAS | D11: =VLOOKUP(B11,'Detalhamento - G200'!A:G,5,) -> 0 | F11: =D11+E11 -> 0
B12: =_xlfn.XLOOKUP(C12,'Detalhamento - G200'!B8:B255,'Detalhamento - G200'!A8:A255,0) -> 1001002002 | C12: MOVIMENTO DE TERRA - ESCOPO MÍNIMO | D12: =VLOOKUP(B12,'Detalhamento - G200'!A:G,5,) -> 0 | F12: =D12+E12 -> 0
B13: =_xlfn.XLOOKUP(C13,'Detalhamento - G200'!B9:B256,'Detalhamento - G200'!A9:A256,0) -> 1001002003 | C13: MOVIMENTAÇÃO DE TERRA | D13: =VLOOKUP(B13,'Detalhamento - G200'!A:G,5,) -> 0 | F13: =D13+E13 -> 0
B14: =_xlfn.XLOOKUP(C14,'Detalhamento - G200'!B10:B257,'Detalhamento - G200'!A10:A257,0) -> 1001002004 | C14: LINHA DE VIDA MOVEL PARA TALUDES | D14: =VLOOKUP(B14,'Detalhamento - G200'!A:G,5,) -> 0 | F14: =D14+E14 -> 0
B15: =_xlfn.XLOOKUP(C15,'Detalhamento - G200'!B11:B258,'Detalhamento - G200'!A11:A258,0) -> 1001002005 | C15: HIDROSSEMEADURA | D15: =VLOOKUP(B15,'Detalhamento - G200'!A:G,5,) -> 0 | F15: =D15+E15 -> 0
B16: =_xlfn.XLOOKUP(C16,'Detalhamento - G200'!B12:B259,'Detalhamento - G200'!A12:A259,0) -> 1001002006 | C16: CONTENÇÕES | D16: =VLOOKUP(B16,'Detalhamento - G200'!A:G,5,) -> 0 | F16: =D16+E16 -> 0
B17: =_xlfn.XLOOKUP(C17,'Detalhamento - G200'!B13:B260,'Detalhamento - G200'!A13:A260,0) -> 1001002007 | C17: ESCAVAÇÃO NO TARDOZ | D17: =VLOOKUP(B17,'Detalhamento - G200'!A:G,5,) -> 0 | F17: =D17+E17 -> 0
B18: =_xlfn.XLOOKUP(C18,'Detalhamento - G200'!B14:B261,'Detalhamento - G200'!A14:A261,0) -> 1001002008 | C18: DRENAGEM | D18: =VLOOKUP(B18,'Detalhamento - G200'!A:G,5,) -> 0 | F18: =D18+E18 -> 0
B19: =_xlfn.XLOOKUP(C19,'Detalhamento - G200'!B15:B262,'Detalhamento - G200'!A15:A262,0) -> 1001003001 | C19: FUNDAÇÃO GALPÃO | D19: =VLOOKUP(B19,'Detalhamento - G200'!A:G,5,) -> 0 | F19: =D19+E19 -> 0
B20: =_xlfn.XLOOKUP(C20,'Detalhamento - G200'!B16:B263,'Detalhamento - G200'!A16:A263,0) -> 1001003002 | C20: SUPERESTRUTURA GALPÃO | D20: =VLOOKUP(B20,'Detalhamento - G200'!A:G,5,) -> 0 | F20: =D20+E20 -> 0 | G20: PREVISÃO - EQUALIZAÇÃO DO CONTRATO T&A
